Workbook

Sheet Start here
A1: Lakeba Investor Portal: investor data
A3: What this file is | B3: One place to record every company, share class, holder, login and holding the portal should know about: Lakeba Group and its ventures. The portal is built and checked from it.
A4: Version | B4: Blank template.
A6: How to fill it in
A7: 1. Companies | B7: Lakeba Group and each venture, with a short code (LKB, EZF…).
A8: 2. Share classes | B8: Each class per company. Class codes start with the company code (EZF-ORD). Add the official number on issue from the register.
A9: 3. Holders | B9: Every legal owner on any register, once, even if they hold in several companies. LKB-GROUP is Lakeba Group Limited (it holds the ventures).
A10: 4. Holdings | B10: One row per holder, class and date. To record a change, add a row with the new date; don’t overwrite.
A11: 5. People | B11: Everyone who will sign in, one row per email. Staff roles (Board, Marketing…) can be listed here; investors have none.
A12: 6. Access | B12: Which holders each person sees. What they see follows from the holdings: an Ezifin-only shareholder sees only Ezifin.
A13: 7. Boards | B13: Directors and company admins per company.
A14: 8. Prices | B14: Reference prices per class (optional).
A15: 9. Holding notes | B15: Notes the holder sees next to a holding (optional).
A16: 10. Checks | B16: Every “Problems” figure should be 0. Red cells on each sheet show which rows.
A18: Legend
A19: Yellow cells, blue text | B19: Fill these in. Columns marked * are required.
A20: Grey cells, black text | B20: Calculated. Don’t type here.
A21: Light grey italic row 3 | B21: An example of the format. It is not imported.
A22: Red cell | B22: A check found a problem in that row.
A23: Header notes | B23: Hover over a column header for an explanation.
A25: Formats | B25: Dates as dd/mm/yyyy. Shares as whole numbers. Percentages with a % sign (65%). Choose list values from the drop-downs.
A26: Confidential | B26: Once filled in, this file contains personal information about investors. Keep it access-controlled.

Sheet Checks
A1: Checks
A2: Everything should read 0 before the file is imported. Filter a sheet’s Check column to find the rows.
A4: Sheet | B4: Rows filled | C4: Problems | D4: What it checks
A5: Companies | B5: =SUMPRODUCT(('Companies'!$A$4:$A$63<>"")*1) | C5: =SUMPRODUCT(('Companies'!$N$4:$N$63<>"")*('Companies'!$N$4:$N$63<>"OK")) | D5: Unique code, required fields, stated Lakeba stake matches the register
A6: Share classes | B6: =SUMPRODUCT(('Share classes'!$B$4:$B$203<>"")*1) | C6: =SUMPRODUCT(('Share classes'!$M$4:$M$203<>"")*('Share classes'!$M$4:$M$203<>"OK")) | D6: Unique code, known company, holdings add up to the official number on issue
A7: Holders | B7: =SUMPRODUCT(('Holders'!$A$4:$A$1003<>"")*1) | C7: =SUMPRODUCT(('Holders'!$H$4:$H$1003<>"")*('Holders'!$H$4:$H$1003<>"OK")) | D7: Unique ID, required fields, has holdings (“No login” is a warning, counted here too)
A8: People | B8: =SUMPRODUCT(('People'!$A$4:$A$1003<>"")*1) | C8: =SUMPRODUCT(('People'!$J$4:$J$1003<>"")*('People'!$J$4:$J$1003<>"OK")) | D8: Unique email, valid address, investors linked to at least one holder
A9: Access | B9: =SUMPRODUCT(('Access'!$A$4:$A$1503<>"")*1) | C9: =SUMPRODUCT(('Access'!$G$4:$G$1503<>"")*('Access'!$G$4:$G$1503<>"OK")) | D9: Email and holder exist, no duplicate links
A10: Holdings | B10: =SUMPRODUCT(('Holdings'!$A$4:$A$2503<>"")*1) | C10: =SUMPRODUCT(('Holdings'!$N$4:$N$2503<>"")*('Holdings'!$N$4:$N$2503<>"OK")) | D10: Holder and class exist, whole shares, no duplicate rows
A11: Boards | B11: =SUMPRODUCT(('Boards'!$A$4:$A$303<>"")*1) | C11: =SUMPRODUCT(('Boards'!$G$4:$G$303<>"")*('Boards'!$G$4:$G$303<>"OK")) | D11: Company and email exist
A12: Prices | B12: =SUMPRODUCT(('Prices'!$A$4:$A$503<>"")*1) | C12: =SUMPRODUCT(('Prices'!$G$4:$G$503<>"")*('Prices'!$G$4:$G$503<>"OK")) | D12: Class exists, no duplicates
A13: Holding notes | B13: =SUMPRODUCT(('Holding notes'!$A$4:$A$503<>"")*1) | C13: =SUMPRODUCT(('Holding notes'!$D$4:$D$503<>"")*('Holding notes'!$D$4:$D$503<>"OK")) | D13: Holder and class exist, one note per holding
A15: Ownership by company
A16: Company | B16: Holders (latest > 0) | C16: Shares (count toward %) | D16: Lakeba % per register
A17: =IF('Companies'!A4="","",'Companies'!A4) | B17: =IF(A17="","",SUMPRODUCT(('Holdings'!$J$4:$J$2503=A17)*('Holdings'!$L$4:$L$2503="Yes")*('Holdings'!$C$4:$C$2503>0))) | C17: =IF(A17="","",SUMIFS('Holdings'!$C$4:$C$2503,'Holdings'!$J$4:$J$2503,A17,'Holdings'!$L$4:$L$2503,"Yes",'Holdings'!$M$4:$M$2503,"Yes")) | D17: =IF(A17="","",'Companies'!M4)
A18: =IF('Companies'!A5="","",'Companies'!A5) | B18: =IF(A18="","",SUMPRODUCT(('Holdings'!$J$4:$J$2503=A18)*('Holdings'!$L$4:$L$2503="Yes")*('Holdings'!$C$4:$C$2503>0))) | C18: =IF(A18="","",SUMIFS('Holdings'!$C$4:$C$2503,'Holdings'!$J$4:$J$2503,A18,'Holdings'!$L$4:$L$2503,"Yes",'Holdings'!$M$4:$M$2503,"Yes")) | D18: =IF(A18="","",'Companies'!M5)
A19: =IF('Companies'!A6="","",'Companies'!A6) | B19: =IF(A19="","",SUMPRODUCT(('Holdings'!$J$4:$J$2503=A19)*('Holdings'!$L$4:$L$2503="Yes")*('Holdings'!$C$4:$C$2503>0))) | C19: =IF(A19="","",SUMIFS('Holdings'!$C$4:$C$2503,'Holdings'!$J$4:$J$2503,A19,'Holdings'!$L$4:$L$2503,"Yes",'Holdings'!$M$4:$M$2503,"Yes")) | D19: =IF(A19="","",'Companies'!M6)
A20: =IF('Companies'!A7="","",'Companies'!A7) | B20: =IF(A20="","",SUMPRODUCT(('Holdings'!$J$4:$J$2503=A20)*('Holdings'!$L$4:$L$2503="Yes")*('Holdings'!$C$4:$C$2503>0))) | C20: =IF(A20="","",SUMIFS('Holdings'!$C$4:$C$2503,'Holdings'!$J$4:$J$2503,A20,'Holdings'!$L$4:$L$2503,"Yes",'Holdings'!$M$4:$M$2503,"Yes")) | D20: =IF(A20="","",'Companies'!M7)
A21: =IF('Companies'!A8="","",'Companies'!A8) | B21: =IF(A21="","",SUMPRODUCT(('Holdings'!$J$4:$J$2503=A21)*('Holdings'!$L$4:$L$2503="Yes")*('Holdings'!$C$4:$C$2503>0))) | C21: =IF(A21="","",SUMIFS('Holdings'!$C$4:$C$2503,'Holdings'!$J$4:$J$2503,A21,'Holdings'!$L$4:$L$2503,"Yes",'Holdings'!$M$4:$M$2503,"Yes")) | D21: =IF(A21="","",'Companies'!M8)
A22: =IF('Companies'!A9="","",'Companies'!A9) | B22: =IF(A22="","",SUMPRODUCT(('Holdings'!$J$4:$J$2503=A22)*('Holdings'!$L$4:$L$2503="Yes")*('Holdings'!$C$4:$C$2503>0))) | C22: =IF(A22="","",SUMIFS('Holdings'!$C$4:$C$2503,'Holdings'!$J$4:$J$2503,A22,'Holdings'!$L$4:$L$2503,"Yes",'Holdings'!$M$4:$M$2503,"Yes")) | D22: =IF(A22="","",'Companies'!M9)
A23: =IF('Companies'!A10="","",'Companies'!A10) | B23: =IF(A23="","",SUMPRODUCT(('Holdings'!$J$4:$J$2503=A23)*('Holdings'!$L$4:$L$2503="Yes")*('Holdings'!$C$4:$C$2503>0))) | C23: =IF(A23="","",SUMIFS('Holdings'!$C$4:$C$2503,'Holdings'!$J$4:$J$2503,A23,'Holdings'!$L$4:$L$2503,"Yes",'Holdings'!$M$4:$M$2503,"Yes")) | D23: =IF(A23="","",'Companies'!M10)
A24: =IF('Companies'!A11="","",'Companies'!A11) | B24: =IF(A24="","",SUMPRODUCT(('Holdings'!$J$4:$J$2503=A24)*('Holdings'!$L$4:$L$2503="Yes")*('Holdings'!$C$4:$C$2503>0))) | C24: =IF(A24="","",SUMIFS('Holdings'!$C$4:$C$2503,'Holdings'!$J$4:$J$2503,A24,'Holdings'!$L$4:$L$2503,"Yes",'Holdings'!$M$4:$M$2503,"Yes")) | D24: =IF(A24="","",'Companies'!M11)
A25: =IF('Companies'!A12="","",'Companies'!A12) | B25: =IF(A25="","",SUMPRODUCT(('Holdings'!$J$4:$J$2503=A25)*('Holdings'!$L$4:$L$2503="Yes")*('Holdings'!$C$4:$C$2503>0))) | C25: =IF(A25="","",SUMIFS('Holdings'!$C$4:$C$2503,'Holdings'!$J$4:$J$2503,A25,'Holdings'!$L$4:$L$2503,"Yes",'Holdings'!$M$4:$M$2503,"Yes")) | D25: =IF(A25="","",'Companies'!M12)
A26: =IF('Companies'!A13="","",'Companies'!A13) | B26: =IF(A26="","",SUMPRODUCT(('Holdings'!$J$4:$J$2503=A26)*('Holdings'!$L$4:$L$2503="Yes")*('Holdings'!$C$4:$C$2503>0))) | C26: =IF(A26="","",SUMIFS('Holdings'!$C$4:$C$2503,'Holdings'!$J$4:$J$2503,A26,'Holdings'!$L$4:$L$2503,"Yes",'Holdings'!$M$4:$M$2503,"Yes")) | D26: =IF(A26="","",'Companies'!M13)
A27: =IF('Companies'!A14="","",'Companies'!A14) | B27: =IF(A27="","",SUMPRODUCT(('Holdings'!$J$4:$J$2503=A27)*('Holdings'!$L$4:$L$2503="Yes")*('Holdings'!$C$4:$C$2503>0))) | C27: =IF(A27="","",SUMIFS('Holdings'!$C$4:$C$2503,'Holdings'!$J$4:$J$2503,A27,'Holdings'!$L$4:$L$2503,"Yes",'Holdings'!$M$4:$M$2503,"Yes")) | D27: =IF(A27="","",'Companies'!M14)
A28: =IF('Companies'!A15="","",'Companies'!A15) | B28: =IF(A28="","",SUMPRODUCT(('Holdings'!$J$4:$J$2503=A28)*('Holdings'!$L$4:$L$2503="Yes")*('Holdings'!$C$4:$C$2503>0))) | C28: =IF(A28="","",SUMIFS('Holdings'!$C$4:$C$2503,'Holdings'!$J$4:$J$2503,A28,'Holdings'!$L$4:$L$2503,"Yes",'Holdings'!$M$4:$M$2503,"Yes")) | D28: =IF(A28="","",'Companies'!M15)

Sheet Lists
A1: Relationship | B1: Portal access | C1: Class type | D1: YesNo | E1: Holder kind | F1: Role | G1: Access level | H1: Position | I1: Price source | J1: Holding source
A2: Group | B2: Full portal | C2: Ordinary | D2: Yes | E2: Individual | F2: Board | G2: Owner | H2: Director | I2: Capital raise | J2: Share register
A3: Controlled venture | B3: Portfolio entry only | C3: Ordinary (non-voting) | D3: No | E3: Company | F3: Marketing | G3: Viewer | H3: Chair | I3: Secondary trade | J3: Registry CSV
A4: Non-controlling investment | B4: Not in portal | C4: Preference | E4: Trust | F4: Legal | H4: Company secretary | I4: Directors’ valuation | J4: Old portal (WordPress)
C5: Options | E5: Super fund | F5: Compliance | H5: Observer | J5: Manual
C6: Convertible note | F6: Admin | H6: Company admin
C7: SAFE
C8: Other

Sheet Companies
A1: Companies | C1: Lakeba Group and every company whose shareholders the portal could serve. One row per company.
A2: Company code * | B2: Legal name | C2: Display name | D2: ACN / ABN | E2: Country | F2: Relationship * | G2: Portal access * | H2: Lakeba stake (stated) | I2: Stake as at | J2: Website | K2: Portal admin email(s) | L2: Notes | M2: Lakeba % per register | N2: Check
A3: EZF | B3: Ezifin Pty Ltd | C3: Ezifin | D3: 123 456 789 | E3: Australia | F3: Controlled venture | G3: Full portal | H3: 0.65 | I3: 46203 | J3: https://ezifin.com | K3: cfo@ezifin.com | O3: ← example row, not imported
A4: LKB | B4: Lakeba Group Limited | C4: Lakeba Group | E4: Australia | F4: Group | G4: Full portal | M4: =IF(OR(A4="",F4="Group"),"",IFERROR(SUMIFS('Holdings'!$C$4:$C$2503,'Holdings'!$J$4:$J$2503,A4,'Holdings'!$A$4:$A$2503,"LKB-GROUP",'Holdings'!$L$4:$L$2503,"Yes",'Holdings'!$M$4:$M$2503,"Yes")/SUMIFS('Holdings'!$C$4:$C$2503,'Holdings'!$J$4:$J$2503,A4,'Holdings'!$L$4:$L$2503,"Yes",'Holdings'!$M$4:$M$2503,"Yes"),"")) | N4: =IF(A4="","",IF(COUNTIF($A$4:$A$63,A4)>1,"Duplicate code",IF(OR(AND(B4="",C4=""),F4="",G4=""),"Missing required field",IF(AND(F4="Controlled venture",H4<>"",M4<>""),IF(ABS(H4-M4)>0.0005,"Stake differs from register","OK"),"OK"))))
A5: EZF | C5: Ezifin | F5: Controlled venture | G5: Full portal | M5: =IF(OR(A5="",F5="Group"),"",IFERROR(SUMIFS('Holdings'!$C$4:$C$2503,'Holdings'!$J$4:$J$2503,A5,'Holdings'!$A$4:$A$2503,"LKB-GROUP",'Holdings'!$L$4:$L$2503,"Yes",'Holdings'!$M$4:$M$2503,"Yes")/SUMIFS('Holdings'!$C$4:$C$2503,'Holdings'!$J$4:$J$2503,A5,'Holdings'!$L$4:$L$2503,"Yes",'Holdings'!$M$4:$M$2503,"Yes"),"")) | N5: =IF(A5="","",IF(COUNTIF($A$4:$A$63,A5)>1,"Duplicate code",IF(OR(AND(B5="",C5=""),F5="",G5=""),"Missing required field",IF(AND(F5="Controlled venture",H5<>"",M5<>""),IF(ABS(H5-M5)>0.0005,"Stake differs from register","OK"),"OK"))))
A6: DOX | C6: DoxAI | F6: Controlled venture | G6: Full portal | M6: =IF(OR(A6="",F6="Group"),"",IFERROR(SUMIFS('Holdings'!$C$4:$C$2503,'Holdings'!$J$4:$J$2503,A6,'Holdings'!$A$4:$A$2503,"LKB-GROUP",'Holdings'!$L$4:$L$2503,"Yes",'Holdings'!$M$4:$M$2503,"Yes")/SUMIFS('Holdings'!$C$4:$C$2503,'Holdings'!$J$4:$J$2503,A6,'Holdings'!$L$4:$L$2503,"Yes",'Holdings'!$M$4:$M$2503,"Yes"),"")) | N6: =IF(A6="","",IF(COUNTIF($A$4:$A$63,A6)>1,"Duplicate code",IF(OR(AND(B6="",C6=""),F6="",G6=""),"Missing required field",IF(AND(F6="Controlled venture",H6<>"",M6<>""),IF(ABS(H6-M6)>0.0005,"Stake differs from register","OK"),"OK"))))
A7: BRK | C7: Bricklet | F7: Controlled venture | G7: Full portal | M7: =IF(OR(A7="",F7="Group"),"",IFERROR(SUMIFS('Holdings'!$C$4:$C$2503,'Holdings'!$J$4:$J$2503,A7,'Holdings'!$A$4:$A$2503,"LKB-GROUP",'Holdings'!$L$4:$L$2503,"Yes",'Holdings'!$M$4:$M$2503,"Yes")/SUMIFS('Holdings'!$C$4:$C$2503,'Holdings'!$J$4:$J$2503,A7,'Holdings'!$L$4:$L$2503,"Yes",'Holdings'!$M$4:$M$2503,"Yes"),"")) | N7: =IF(A7="","",IF(COUNTIF($A$4:$A$63,A7)>1,"Duplicate code",IF(OR(AND(B7="",C7=""),F7="",G7=""),"Missing required field",IF(AND(F7="Controlled venture",H7<>"",M7<>""),IF(ABS(H7-M7)>0.0005,"Stake differs from register","OK"),"OK"))))
A8: SHF | C8: Shelfie | F8: Controlled venture | G8: Full portal | M8: =IF(OR(A8="",F8="Group"),"",IFERROR(SUMIFS('Holdings'!$C$4:$C$2503,'Holdings'!$J$4:$J$2503,A8,'Holdings'!$A$4:$A$2503,"LKB-GROUP",'Holdings'!$L$4:$L$2503,"Yes",'Holdings'!$M$4:$M$2503,"Yes")/SUMIFS('Holdings'!$C$4:$C$2503,'Holdings'!$J$4:$J$2503,A8,'Holdings'!$L$4:$L$2503,"Yes",'Holdings'!$M$4:$M$2503,"Yes"),"")) | N8: =IF(A8="","",IF(COUNTIF($A$4:$A$63,A8)>1,"Duplicate code",IF(OR(AND(B8="",C8=""),F8="",G8=""),"Missing required field",IF(AND(F8="Controlled venture",H8<>"",M8<>""),IF(ABS(H8-M8)>0.0005,"Stake differs from register","OK"),"OK"))))
A9: WHK | C9: Whitehawk | F9: Non-controlling investment | G9: Portfolio entry only | M9: =IF(OR(A9="",F9="Group"),"",IFERROR(SUMIFS('Holdings'!$C$4:$C$2503,'Holdings'!$J$4:$J$2503,A9,'Holdings'!$A$4:$A$2503,"LKB-GROUP",'Holdings'!$L$4:$L$2503,"Yes",'Holdings'!$M$4:$M$2503,"Yes")/SUMIFS('Holdings'!$C$4:$C$2503,'Holdings'!$J$4:$J$2503,A9,'Holdings'!$L$4:$L$2503,"Yes",'Holdings'!$M$4:$M$2503,"Yes"),"")) | N9: =IF(A9="","",IF(COUNTIF($A$4:$A$63,A9)>1,"Duplicate code",IF(OR(AND(B9="",C9=""),F9="",G9=""),"Missing required field",IF(AND(F9="Controlled venture",H9<>"",M9<>""),IF(ABS(H9-M9)>0.0005,"Stake differs from register","OK"),"OK"))))
A10: MIST | C10: MIST | F10: Non-controlling investment | G10: Portfolio entry only | M10: =IF(OR(A10="",F10="Group"),"",IFERROR(SUMIFS('Holdings'!$C$4:$C$2503,'Holdings'!$J$4:$J$2503,A10,'Holdings'!$A$4:$A$2503,"LKB-GROUP",'Holdings'!$L$4:$L$2503,"Yes",'Holdings'!$M$4:$M$2503,"Yes")/SUMIFS('Holdings'!$C$4:$C$2503,'Holdings'!$J$4:$J$2503,A10,'Holdings'!$L$4:$L$2503,"Yes",'Holdings'!$M$4:$M$2503,"Yes"),"")) | N10: =IF(A10="","",IF(COUNTIF($A$4:$A$63,A10)>1,"Duplicate code",IF(OR(AND(B10="",C10=""),F10="",G10=""),"Missing required field",IF(AND(F10="Controlled venture",H10<>"",M10<>""),IF(ABS(H10-M10)>0.0005,"Stake differs from register","OK"),"OK"))))
A11: AST | C11: Assetora | F11: Non-controlling investment | G11: Portfolio entry only | M11: =IF(OR(A11="",F11="Group"),"",IFERROR(SUMIFS('Holdings'!$C$4:$C$2503,'Holdings'!$J$4:$J$2503,A11,'Holdings'!$A$4:$A$2503,"LKB-GROUP",'Holdings'!$L$4:$L$2503,"Yes",'Holdings'!$M$4:$M$2503,"Yes")/SUMIFS('Holdings'!$C$4:$C$2503,'Holdings'!$J$4:$J$2503,A11,'Holdings'!$L$4:$L$2503,"Yes",'Holdings'!$M$4:$M$2503,"Yes"),"")) | N11: =IF(A11="","",IF(COUNTIF($A$4:$A$63,A11)>1,"Duplicate code",IF(OR(AND(B11="",C11=""),F11="",G11=""),"Missing required field",IF(AND(F11="Controlled venture",H11<>"",M11<>""),IF(ABS(H11-M11)>0.0005,"Stake differs from register","OK"),"OK"))))
A12: APR | C12: Appreci | F12: Non-controlling investment | G12: Portfolio entry only | M12: =IF(OR(A12="",F12="Group"),"",IFERROR(SUMIFS('Holdings'!$C$4:$C$2503,'Holdings'!$J$4:$J$2503,A12,'Holdings'!$A$4:$A$2503,"LKB-GROUP",'Holdings'!$L$4:$L$2503,"Yes",'Holdings'!$M$4:$M$2503,"Yes")/SUMIFS('Holdings'!$C$4:$C$2503,'Holdings'!$J$4:$J$2503,A12,'Holdings'!$L$4:$L$2503,"Yes",'Holdings'!$M$4:$M$2503,"Yes"),"")) | N12: =IF(A12="","",IF(COUNTIF($A$4:$A$63,A12)>1,"Duplicate code",IF(OR(AND(B12="",C12=""),F12="",G12=""),"Missing required field",IF(AND(F12="Controlled venture",H12<>"",M12<>""),IF(ABS(H12-M12)>0.0005,"Stake differs from register","OK"),"OK"))))
A13: ZUC | C13: Zucoins | F13: Non-controlling investment | G13: Portfolio entry only | M13: =IF(OR(A13="",F13="Group"),"",IFERROR(SUMIFS('Holdings'!$C$4:$C$2503,'Holdings'!$J$4:$J$2503,A13,'Holdings'!$A$4:$A$2503,"LKB-GROUP",'Holdings'!$L$4:$L$2503,"Yes",'Holdings'!$M$4:$M$2503,"Yes")/SUMIFS('Holdings'!$C$4:$C$2503,'Holdings'!$J$4:$J$2503,A13,'Holdings'!$L$4:$L$2503,"Yes",'Holdings'!$M$4:$M$2503,"Yes"),"")) | N13: =IF(A13="","",IF(COUNTIF($A$4:$A$63,A13)>1,"Duplicate code",IF(OR(AND(B13="",C13=""),F13="",G13=""),"Missing required field",IF(AND(F13="Controlled venture",H13<>"",M13<>""),IF(ABS(H13-M13)>0.0005,"Stake differs from register","OK"),"OK"))))
A14: EZP | C14: EziProp | F14: Non-controlling investment | G14: Portfolio entry only | M14: =IF(OR(A14="",F14="Group"),"",IFERROR(SUMIFS('Holdings'!$C$4:$C$2503,'Holdings'!$J$4:$J$2503,A14,'Holdings'!$A$4:$A$2503,"LKB-GROUP",'Holdings'!$L$4:$L$2503,"Yes",'Holdings'!$M$4:$M$2503,"Yes")/SUMIFS('Holdings'!$C$4:$C$2503,'Holdings'!$J$4:$J$2503,A14,'Holdings'!$L$4:$L$2503,"Yes",'Holdings'!$M$4:$M$2503,"Yes"),"")) | N14: =IF(A14="","",IF(COUNTIF($A$4:$A$63,A14)>1,"Duplicate code",IF(OR(AND(B14="",C14=""),F14="",G14=""),"Missing required field",IF(AND(F14="Controlled venture",H14<>"",M14<>""),IF(ABS(H14-M14)>0.0005,"Stake differs from register","OK"),"OK"))))
M15: =IF(OR(A15="",F15="Group"),"",IFERROR(SUMIFS('Holdings'!$C$4:$C$2503,'Holdings'!$J$4:$J$2503,A15,'Holdings'!$A$4:$A$2503,"LKB-GROUP",'Holdings'!$L$4:$L$2503,"Yes",'Holdings'!$M$4:$M$2503,"Yes")/SUMIFS('Holdings'!$C$4:$C$2503,'Holdings'!$J$4:$J$2503,A15,'Holdings'!$L$4:$L$2503,"Yes",'Holdings'!$M$4:$M$2503,"Yes"),"")) | N15: =IF(A15="","",IF(COUNTIF($A$4:$A$63,A15)>1,"Duplicate code",IF(OR(AND(B15="",C15=""),F15="",G15=""),"Missing required field",IF(AND(F15="Controlled venture",H15<>"",M15<>""),IF(ABS(H15-M15)>0.0005,"Stake differs from register","OK"),"OK"))))
M16: =IF(OR(A16="",F16="Group"),"",IFERROR(SUMIFS('Holdings'!$C$4:$C$2503,'Holdings'!$J$4:$J$2503,A16,'Holdings'!$A$4:$A$2503,"LKB-GROUP",'Holdings'!$L$4:$L$2503,"Yes",'Holdings'!$M$4:$M$2503,"Yes")/SUMIFS('Holdings'!$C$4:$C$2503,'Holdings'!$J$4:$J$2503,A16,'Holdings'!$L$4:$L$2503,"Yes",'Holdings'!$M$4:$M$2503,"Yes"),"")) | N16: =IF(A16="","",IF(COUNTIF($A$4:$A$63,A16)>1,"Duplicate code",IF(OR(AND(B16="",C16=""),F16="",G16=""),"Missing required field",IF(AND(F16="Controlled venture",H16<>"",M16<>""),IF(ABS(H16-M16)>0.0005,"Stake differs from register","OK"),"OK"))))
M17: =IF(OR(A17="",F17="Group"),"",IFERROR(SUMIFS('Holdings'!$C$4:$C$2503,'Holdings'!$J$4:$J$2503,A17,'Holdings'!$A$4:$A$2503,"LKB-GROUP",'Holdings'!$L$4:$L$2503,"Yes",'Holdings'!$M$4:$M$2503,"Yes")/SUMIFS('Holdings'!$C$4:$C$2503,'Holdings'!$J$4:$J$2503,A17,'Holdings'!$L$4:$L$2503,"Yes",'Holdings'!$M$4:$M$2503,"Yes"),"")) | N17: =IF(A17="","",IF(COUNTIF($A$4:$A$63,A17)>1,"Duplicate code",IF(OR(AND(B17="",C17=""),F17="",G17=""),"Missing required field",IF(AND(F17="Controlled venture",H17<>"",M17<>""),IF(ABS(H17-M17)>0.0005,"Stake differs from register","OK"),"OK"))))
M18: =IF(OR(A18="",F18="Group"),"",IFERROR(SUMIFS('Holdings'!$C$4:$C$2503,'Holdings'!$J$4:$J$2503,A18,'Holdings'!$A$4:$A$2503,"LKB-GROUP",'Holdings'!$L$4:$L$2503,"Yes",'Holdings'!$M$4:$M$2503,"Yes")/SUMIFS('Holdings'!$C$4:$C$2503,'Holdings'!$J$4:$J$2503,A18,'Holdings'!$L$4:$L$2503,"Yes",'Holdings'!$M$4:$M$2503,"Yes"),"")) | N18: =IF(A18="","",IF(COUNTIF($A$4:$A$63,A18)>1,"Duplicate code",IF(OR(AND(B18="",C18=""),F18="",G18=""),"Missing required field",IF(AND(F18="Controlled venture",H18<>"",M18<>""),IF(ABS(H18-M18)>0.0005,"Stake differs from register","OK"),"OK"))))
M19: =IF(OR(A19="",F19="Group"),"",IFERROR(SUMIFS('Holdings'!$C$4:$C$2503,'Holdings'!$J$4:$J$2503,A19,'Holdings'!$A$4:$A$2503,"LKB-GROUP",'Holdings'!$L$4:$L$2503,"Yes",'Holdings'!$M$4:$M$2503,"Yes")/SUMIFS('Holdings'!$C$4:$C$2503,'Holdings'!$J$4:$J$2503,A19,'Holdings'!$L$4:$L$2503,"Yes",'Holdings'!$M$4:$M$2503,"Yes"),"")) | N19: =IF(A19="","",IF(COUNTIF($A$4:$A$63,A19)>1,"Duplicate code",IF(OR(AND(B19="",C19=""),F19="",G19=""),"Missing required field",IF(AND(F19="Controlled venture",H19<>"",M19<>""),IF(ABS(H19-M19)>0.0005,"Stake differs from register","OK"),"OK"))))
M20: =IF(OR(A20="",F20="Group"),"",IFERROR(SUMIFS('Holdings'!$C$4:$C$2503,'Holdings'!$J$4:$J$2503,A20,'Holdings'!$A$4:$A$2503,"LKB-GROUP",'Holdings'!$L$4:$L$2503,"Yes",'Holdings'!$M$4:$M$2503,"Yes")/SUMIFS('Holdings'!$C$4:$C$2503,'Holdings'!$J$4:$J$2503,A20,'Holdings'!$L$4:$L$2503,"Yes",'Holdings'!$M$4:$M$2503,"Yes"),"")) | N20: =IF(A20="","",IF(COUNTIF($A$4:$A$63,A20)>1,"Duplicate code",IF(OR(AND(B20="",C20=""),F20="",G20=""),"Missing required field",IF(AND(F20="Controlled venture",H20<>"",M20<>""),IF(ABS(H20-M20)>0.0005,"Stake differs from register","OK"),"OK"))))
M21: =IF(OR(A21="",F21="Group"),"",IFERROR(SUMIFS('Holdings'!$C$4:$C$2503,'Holdings'!$J$4:$J$2503,A21,'Holdings'!$A$4:$A$2503,"LKB-GROUP",'Holdings'!$L$4:$L$2503,"Yes",'Holdings'!$M$4:$M$2503,"Yes")/SUMIFS('Holdings'!$C$4:$C$2503,'Holdings'!$J$4:$J$2503,A21,'Holdings'!$L$4:$L$2503,"Yes",'Holdings'!$M$4:$M$2503,"Yes"),"")) | N21: =IF(A21="","",IF(COUNTIF($A$4:$A$63,A21)>1,"Duplicate code",IF(OR(AND(B21="",C21=""),F21="",G21=""),"Missing required field",IF(AND(F21="Controlled venture",H21<>"",M21<>""),IF(ABS(H21-M21)>0.0005,"Stake differs from register","OK"),"OK"))))
M22: =IF(OR(A22="",F22="Group"),"",IFERROR(SUMIFS('Holdings'!$C$4:$C$2503,'Holdings'!$J$4:$J$2503,A22,'Holdings'!$A$4:$A$2503,"LKB-GROUP",'Holdings'!$L$4:$L$2503,"Yes",'Holdings'!$M$4:$M$2503,"Yes")/SUMIFS('Holdings'!$C$4:$C$2503,'Holdings'!$J$4:$J$2503,A22,'Holdings'!$L$4:$L$2503,"Yes",'Holdings'!$M$4:$M$2503,"Yes"),"")) | N22: =IF(A22="","",IF(COUNTIF($A$4:$A$63,A22)>1,"Duplicate code",IF(OR(AND(B22="",C22=""),F22="",G22=""),"Missing required field",IF(AND(F22="Controlled venture",H22<>"",M22<>""),IF(ABS(H22-M22)>0.0005,"Stake differs from register","OK"),"OK"))))
M23: =IF(OR(A23="",F23="Group"),"",IFERROR(SUMIFS('Holdings'!$C$4:$C$2503,'Holdings'!$J$4:$J$2503,A23,'Holdings'!$A$4:$A$2503,"LKB-GROUP",'Holdings'!$L$4:$L$2503,"Yes",'Holdings'!$M$4:$M$2503,"Yes")/SUMIFS('Holdings'!$C$4:$C$2503,'Holdings'!$J$4:$J$2503,A23,'Holdings'!$L$4:$L$2503,"Yes",'Holdings'!$M$4:$M$2503,"Yes"),"")) | N23: =IF(A23="","",IF(COUNTIF($A$4:$A$63,A23)>1,"Duplicate code",IF(OR(AND(B23="",C23=""),F23="",G23=""),"Missing required field",IF(AND(F23="Controlled venture",H23<>"",M23<>""),IF(ABS(H23-M23)>0.0005,"Stake differs from register","OK"),"OK"))))
M24: =IF(OR(A24="",F24="Group"),"",IFERROR(SUMIFS('Holdings'!$C$4:$C$2503,'Holdings'!$J$4:$J$2503,A24,'Holdings'!$A$4:$A$2503,"LKB-GROUP",'Holdings'!$L$4:$L$2503,"Yes",'Holdings'!$M$4:$M$2503,"Yes")/SUMIFS('Holdings'!$C$4:$C$2503,'Holdings'!$J$4:$J$2503,A24,'Holdings'!$L$4:$L$2503,"Yes",'Holdings'!$M$4:$M$2503,"Yes"),"")) | N24: =IF(A24="","",IF(COUNTIF($A$4:$A$63,A24)>1,"Duplicate code",IF(OR(AND(B24="",C24=""),F24="",G24=""),"Missing required field",IF(AND(F24="Controlled venture",H24<>"",M24<>""),IF(ABS(H24-M24)>0.0005,"Stake differs from register","OK"),"OK"))))
M25: =IF(OR(A25="",F25="Group"),"",IFERROR(SUMIFS('Holdings'!$C$4:$C$2503,'Holdings'!$J$4:$J$2503,A25,'Holdings'!$A$4:$A$2503,"LKB-GROUP",'Holdings'!$L$4:$L$2503,"Yes",'Holdings'!$M$4:$M$2503,"Yes")/SUMIFS('Holdings'!$C$4:$C$2503,'Holdings'!$J$4:$J$2503,A25,'Holdings'!$L$4:$L$2503,"Yes",'Holdings'!$M$4:$M$2503,"Yes"),"")) | N25: =IF(A25="","",IF(COUNTIF($A$4:$A$63,A25)>1,"Duplicate code",IF(OR(AND(B25="",C25=""),F25="",G25=""),"Missing required field",IF(AND(F25="Controlled venture",H25<>"",M25<>""),IF(ABS(H25-M25)>0.0005,"Stake differs from register","OK"),"OK"))))
M26: =IF(OR(A26="",F26="Group"),"",IFERROR(SUMIFS('Holdings'!$C$4:$C$2503,'Holdings'!$J$4:$J$2503,A26,'Holdings'!$A$4:$A$2503,"LKB-GROUP",'Holdings'!$L$4:$L$2503,"Yes",'Holdings'!$M$4:$M$2503,"Yes")/SUMIFS('Holdings'!$C$4:$C$2503,'Holdings'!$J$4:$J$2503,A26,'Holdings'!$L$4:$L$2503,"Yes",'Holdings'!$M$4:$M$2503,"Yes"),"")) | N26: =IF(A26="","",IF(COUNTIF($A$4:$A$63,A26)>1,"Duplicate code",IF(OR(AND(B26="",C26=""),F26="",G26=""),"Missing required field",IF(AND(F26="Controlled venture",H26<>"",M26<>""),IF(ABS(H26-M26)>0.0005,"Stake differs from register","OK"),"OK"))))
... M63: =IF(OR(A63="",F63="Group"),"",IFERROR(SUMIFS('Holdings'!$C$4:$C$2503,'Holdings'!$J$4:$J$2503,A63,'Holdings'!$A$4:$A$2503,"LKB-GROUP",'Holdings'!$L$4:$L$2503,"Yes",'Holdings'!$M$4:$M$2503,"Yes")/SUMIFS('Holdings'!$C$4:$C$2503,'Holdings'!$J$4:$J$2503,A63,'Holdings'!$L$4:$L$2503,"Yes",'Holdings'!$M$4:$M$2503,"Yes"),"")) | N63: =IF(A63="","",IF(COUNTIF($A$4:$A$63,A63)>1,"Duplicate code",IF(OR(AND(B63="",C63=""),F63="",G63=""),"Missing required field",IF(AND(F63="Controlled venture",H63<>"",M63<>""),IF(ABS(H63-M63)>0.0005,"Stake differs from register","OK"),"OK"))))

Sheet Share classes
A1: Share classes | C1: Every class of shares (or notes/options) per company. Holdings refer to the class code.
A2: Company code * | B2: Class code * | C2: Class name * | D2: Type * | E2: Voting * | F2: Counts toward % * | G2: Official on issue | H2: Official as at | I2: Currency | J2: Notes | K2: Total in this file | L2: Difference | M2: Check
A3: EZF | B3: EZF-ORD | C3: Ordinary shares | D3: Ordinary | E3: Yes | F3: Yes | G3: 10000000 | H3: 46203 | I3: AUD | N3: ← example row, not imported
A4: LKB | B4: LKB-ORD | C4: Ordinary shares | D4: Ordinary | E4: Yes | F4: Yes | I4: AUD | K4: =IF(B4="","",SUMIFS('Holdings'!$C$4:$C$2503,'Holdings'!$B$4:$B$2503,B4,'Holdings'!$L$4:$L$2503,"Yes")) | L4: =IF(OR(B4="",G4=""),"",G4-K4) | M4: =IF(B4="","",IF(COUNTIF($B$4:$B$203,B4)>1,"Duplicate class code",IF(COUNTIF('Companies'!$A$4:$A$63,A4)=0,"Unknown company",IF(OR(C4="",D4="",E4="",F4=""),"Missing required field",IF(AND(G4<>"",H4=""),"Add the official as-at date",IF(AND(L4<>"",L4<>0),"Doesn’t add up to official","OK"))))))
A5: LKB | B5: LKB-F | C5: F class shares (non-voting) | D5: Ordinary (non-voting) | E5: No | F5: Yes | I5: AUD | K5: =IF(B5="","",SUMIFS('Holdings'!$C$4:$C$2503,'Holdings'!$B$4:$B$2503,B5,'Holdings'!$L$4:$L$2503,"Yes")) | L5: =IF(OR(B5="",G5=""),"",G5-K5) | M5: =IF(B5="","",IF(COUNTIF($B$4:$B$203,B5)>1,"Duplicate class code",IF(COUNTIF('Companies'!$A$4:$A$63,A5)=0,"Unknown company",IF(OR(C5="",D5="",E5="",F5=""),"Missing required field",IF(AND(G5<>"",H5=""),"Add the official as-at date",IF(AND(L5<>"",L5<>0),"Doesn’t add up to official","OK"))))))
A6: EZF | B6: EZF-ORD | C6: Ordinary shares | D6: Ordinary | E6: Yes | F6: Yes | I6: AUD | K6: =IF(B6="","",SUMIFS('Holdings'!$C$4:$C$2503,'Holdings'!$B$4:$B$2503,B6,'Holdings'!$L$4:$L$2503,"Yes")) | L6: =IF(OR(B6="",G6=""),"",G6-K6) | M6: =IF(B6="","",IF(COUNTIF($B$4:$B$203,B6)>1,"Duplicate class code",IF(COUNTIF('Companies'!$A$4:$A$63,A6)=0,"Unknown company",IF(OR(C6="",D6="",E6="",F6=""),"Missing required field",IF(AND(G6<>"",H6=""),"Add the official as-at date",IF(AND(L6<>"",L6<>0),"Doesn’t add up to official","OK"))))))
A7: DOX | B7: DOX-ORD | C7: Ordinary shares | D7: Ordinary | E7: Yes | F7: Yes | I7: AUD | K7: =IF(B7="","",SUMIFS('Holdings'!$C$4:$C$2503,'Holdings'!$B$4:$B$2503,B7,'Holdings'!$L$4:$L$2503,"Yes")) | L7: =IF(OR(B7="",G7=""),"",G7-K7) | M7: =IF(B7="","",IF(COUNTIF($B$4:$B$203,B7)>1,"Duplicate class code",IF(COUNTIF('Companies'!$A$4:$A$63,A7)=0,"Unknown company",IF(OR(C7="",D7="",E7="",F7=""),"Missing required field",IF(AND(G7<>"",H7=""),"Add the official as-at date",IF(AND(L7<>"",L7<>0),"Doesn’t add up to official","OK"))))))
A8: BRK | B8: BRK-ORD | C8: Ordinary shares | D8: Ordinary | E8: Yes | F8: Yes | I8: AUD | K8: =IF(B8="","",SUMIFS('Holdings'!$C$4:$C$2503,'Holdings'!$B$4:$B$2503,B8,'Holdings'!$L$4:$L$2503,"Yes")) | L8: =IF(OR(B8="",G8=""),"",G8-K8) | M8: =IF(B8="","",IF(COUNTIF($B$4:$B$203,B8)>1,"Duplicate class code",IF(COUNTIF('Companies'!$A$4:$A$63,A8)=0,"Unknown company",IF(OR(C8="",D8="",E8="",F8=""),"Missing required field",IF(AND(G8<>"",H8=""),"Add the official as-at date",IF(AND(L8<>"",L8<>0),"Doesn’t add up to official","OK"))))))
A9: SHF | B9: SHF-ORD | C9: Ordinary shares | D9: Ordinary | E9: Yes | F9: Yes | I9: AUD | K9: =IF(B9="","",SUMIFS('Holdings'!$C$4:$C$2503,'Holdings'!$B$4:$B$2503,B9,'Holdings'!$L$4:$L$2503,"Yes")) | L9: =IF(OR(B9="",G9=""),"",G9-K9) | M9: =IF(B9="","",IF(COUNTIF($B$4:$B$203,B9)>1,"Duplicate class code",IF(COUNTIF('Companies'!$A$4:$A$63,A9)=0,"Unknown company",IF(OR(C9="",D9="",E9="",F9=""),"Missing required field",IF(AND(G9<>"",H9=""),"Add the official as-at date",IF(AND(L9<>"",L9<>0),"Doesn’t add up to official","OK"))))))
K10: =IF(B10="","",SUMIFS('Holdings'!$C$4:$C$2503,'Holdings'!$B$4:$B$2503,B10,'Holdings'!$L$4:$L$2503,"Yes")) | L10: =IF(OR(B10="",G10=""),"",G10-K10) | M10: =IF(B10="","",IF(COUNTIF($B$4:$B$203,B10)>1,"Duplicate class code",IF(COUNTIF('Companies'!$A$4:$A$63,A10)=0,"Unknown company",IF(OR(C10="",D10="",E10="",F10=""),"Missing required field",IF(AND(G10<>"",H10=""),"Add the official as-at date",IF(AND(L10<>"",L10<>0),"Doesn’t add up to official","OK"))))))
K11: =IF(B11="","",SUMIFS('Holdings'!$C$4:$C$2503,'Holdings'!$B$4:$B$2503,B11,'Holdings'!$L$4:$L$2503,"Yes")) | L11: =IF(OR(B11="",G11=""),"",G11-K11) | M11: =IF(B11="","",IF(COUNTIF($B$4:$B$203,B11)>1,"Duplicate class code",IF(COUNTIF('Companies'!$A$4:$A$63,A11)=0,"Unknown company",IF(OR(C11="",D11="",E11="",F11=""),"Missing required field",IF(AND(G11<>"",H11=""),"Add the official as-at date",IF(AND(L11<>"",L11<>0),"Doesn’t add up to official","OK"))))))
K12: =IF(B12="","",SUMIFS('Holdings'!$C$4:$C$2503,'Holdings'!$B$4:$B$2503,B12,'Holdings'!$L$4:$L$2503,"Yes")) | L12: =IF(OR(B12="",G12=""),"",G12-K12) | M12: =IF(B12="","",IF(COUNTIF($B$4:$B$203,B12)>1,"Duplicate class code",IF(COUNTIF('Companies'!$A$4:$A$63,A12)=0,"Unknown company",IF(OR(C12="",D12="",E12="",F12=""),"Missing required field",IF(AND(G12<>"",H12=""),"Add the official as-at date",IF(AND(L12<>"",L12<>0),"Doesn’t add up to official","OK"))))))
K13: =IF(B13="","",SUMIFS('Holdings'!$C$4:$C$2503,'Holdings'!$B$4:$B$2503,B13,'Holdings'!$L$4:$L$2503,"Yes")) | L13: =IF(OR(B13="",G13=""),"",G13-K13) | M13: =IF(B13="","",IF(COUNTIF($B$4:$B$203,B13)>1,"Duplicate class code",IF(COUNTIF('Companies'!$A$4:$A$63,A13)=0,"Unknown company",IF(OR(C13="",D13="",E13="",F13=""),"Missing required field",IF(AND(G13<>"",H13=""),"Add the official as-at date",IF(AND(L13<>"",L13<>0),"Doesn’t add up to official","OK"))))))
K14: =IF(B14="","",SUMIFS('Holdings'!$C$4:$C$2503,'Holdings'!$B$4:$B$2503,B14,'Holdings'!$L$4:$L$2503,"Yes")) | L14: =IF(OR(B14="",G14=""),"",G14-K14) | M14: =IF(B14="","",IF(COUNTIF($B$4:$B$203,B14)>1,"Duplicate class code",IF(COUNTIF('Companies'!$A$4:$A$63,A14)=0,"Unknown company",IF(OR(C14="",D14="",E14="",F14=""),"Missing required field",IF(AND(G14<>"",H14=""),"Add the official as-at date",IF(AND(L14<>"",L14<>0),"Doesn’t add up to official","OK"))))))
K15: =IF(B15="","",SUMIFS('Holdings'!$C$4:$C$2503,'Holdings'!$B$4:$B$2503,B15,'Holdings'!$L$4:$L$2503,"Yes")) | L15: =IF(OR(B15="",G15=""),"",G15-K15) | M15: =IF(B15="","",IF(COUNTIF($B$4:$B$203,B15)>1,"Duplicate class code",IF(COUNTIF('Companies'!$A$4:$A$63,A15)=0,"Unknown company",IF(OR(C15="",D15="",E15="",F15=""),"Missing required field",IF(AND(G15<>"",H15=""),"Add the official as-at date",IF(AND(L15<>"",L15<>0),"Doesn’t add up to official","OK"))))))
K16: =IF(B16="","",SUMIFS('Holdings'!$C$4:$C$2503,'Holdings'!$B$4:$B$2503,B16,'Holdings'!$L$4:$L$2503,"Yes")) | L16: =IF(OR(B16="",G16=""),"",G16-K16) | M16: =IF(B16="","",IF(COUNTIF($B$4:$B$203,B16)>1,"Duplicate class code",IF(COUNTIF('Companies'!$A$4:$A$63,A16)=0,"Unknown company",IF(OR(C16="",D16="",E16="",F16=""),"Missing required field",IF(AND(G16<>"",H16=""),"Add the official as-at date",IF(AND(L16<>"",L16<>0),"Doesn’t add up to official","OK"))))))
K17: =IF(B17="","",SUMIFS('Holdings'!$C$4:$C$2503,'Holdings'!$B$4:$B$2503,B17,'Holdings'!$L$4:$L$2503,"Yes")) | L17: =IF(OR(B17="",G17=""),"",G17-K17) | M17: =IF(B17="","",IF(COUNTIF($B$4:$B$203,B17)>1,"Duplicate class code",IF(COUNTIF('Companies'!$A$4:$A$63,A17)=0,"Unknown company",IF(OR(C17="",D17="",E17="",F17=""),"Missing required field",IF(AND(G17<>"",H17=""),"Add the official as-at date",IF(AND(L17<>"",L17<>0),"Doesn’t add up to official","OK"))))))
K18: =IF(B18="","",SUMIFS('Holdings'!$C$4:$C$2503,'Holdings'!$B$4:$B$2503,B18,'Holdings'!$L$4:$L$2503,"Yes")) | L18: =IF(OR(B18="",G18=""),"",G18-K18) | M18: =IF(B18="","",IF(COUNTIF($B$4:$B$203,B18)>1,"Duplicate class code",IF(COUNTIF('Companies'!$A$4:$A$63,A18)=0,"Unknown company",IF(OR(C18="",D18="",E18="",F18=""),"Missing required field",IF(AND(G18<>"",H18=""),"Add the official as-at date",IF(AND(L18<>"",L18<>0),"Doesn’t add up to official","OK"))))))
K19: =IF(B19="","",SUMIFS('Holdings'!$C$4:$C$2503,'Holdings'!$B$4:$B$2503,B19,'Holdings'!$L$4:$L$2503,"Yes")) | L19: =IF(OR(B19="",G19=""),"",G19-K19) | M19: =IF(B19="","",IF(COUNTIF($B$4:$B$203,B19)>1,"Duplicate class code",IF(COUNTIF('Companies'!$A$4:$A$63,A19)=0,"Unknown company",IF(OR(C19="",D19="",E19="",F19=""),"Missing required field",IF(AND(G19<>"",H19=""),"Add the official as-at date",IF(AND(L19<>"",L19<>0),"Doesn’t add up to official","OK"))))))
K20: =IF(B20="","",SUMIFS('Holdings'!$C$4:$C$2503,'Holdings'!$B$4:$B$2503,B20,'Holdings'!$L$4:$L$2503,"Yes")) | L20: =IF(OR(B20="",G20=""),"",G20-K20) | M20: =IF(B20="","",IF(COUNTIF($B$4:$B$203,B20)>1,"Duplicate class code",IF(COUNTIF('Companies'!$A$4:$A$63,A20)=0,"Unknown company",IF(OR(C20="",D20="",E20="",F20=""),"Missing required field",IF(AND(G20<>"",H20=""),"Add the official as-at date",IF(AND(L20<>"",L20<>0),"Doesn’t add up to official","OK"))))))
K21: =IF(B21="","",SUMIFS('Holdings'!$C$4:$C$2503,'Holdings'!$B$4:$B$2503,B21,'Holdings'!$L$4:$L$2503,"Yes")) | L21: =IF(OR(B21="",G21=""),"",G21-K21) | M21: =IF(B21="","",IF(COUNTIF($B$4:$B$203,B21)>1,"Duplicate class code",IF(COUNTIF('Companies'!$A$4:$A$63,A21)=0,"Unknown company",IF(OR(C21="",D21="",E21="",F21=""),"Missing required field",IF(AND(G21<>"",H21=""),"Add the official as-at date",IF(AND(L21<>"",L21<>0),"Doesn’t add up to official","OK"))))))
... K203: =IF(B203="","",SUMIFS('Holdings'!$C$4:$C$2503,'Holdings'!$B$4:$B$2503,B203,'Holdings'!$L$4:$L$2503,"Yes")) | L203: =IF(OR(B203="",G203=""),"",G203-K203) | M203: =IF(B203="","",IF(COUNTIF($B$4:$B$203,B203)>1,"Duplicate class code",IF(COUNTIF('Companies'!$A$4:$A$63,A203)=0,"Unknown company",IF(OR(C203="",D203="",E203="",F203=""),"Missing required field",IF(AND(G203<>"",H203=""),"Add the official as-at date",IF(AND(L203<>"",L203<>0),"Doesn’t add up to official","OK"))))))

Sheet Holders
A1: Holders | C1: The legal owners as they appear on the registers: people, companies, trusts, super funds. One row per holder, used across all companies.
A2: Holder ID * | B2: Holder name (as on register) * | C2: Kind * | D2: ACN / ABN / trust details | E2: Notes | F2: Holdings rows | G2: Logins with access | H2: Check
A3: H-0001 | B3: Jane Citizen | C3: Individual | I3: ← example row, not imported
A4: LKB-GROUP | B4: Lakeba Group Limited | C4: Company | E4: Holds Lakeba’s shares in each venture | F4: =IF(A4="","",COUNTIF('Holdings'!$A$4:$A$2503,A4)) | G4: =IF(A4="","",COUNTIF('Access'!$B$4:$B$1503,A4)) | H4: =IF(A4="","",IF(COUNTIF($A$4:$A$1003,A4)>1,"Duplicate holder ID",IF(OR(B4="",C4=""),"Missing required field",IF(F4=0,"No holdings",IF(AND(G4=0,A4<>"LKB-GROUP"),"No login (ok if not invited)","OK")))))
F5: =IF(A5="","",COUNTIF('Holdings'!$A$4:$A$2503,A5)) | G5: =IF(A5="","",COUNTIF('Access'!$B$4:$B$1503,A5)) | H5: =IF(A5="","",IF(COUNTIF($A$4:$A$1003,A5)>1,"Duplicate holder ID",IF(OR(B5="",C5=""),"Missing required field",IF(F5=0,"No holdings",IF(AND(G5=0,A5<>"LKB-GROUP"),"No login (ok if not invited)","OK")))))
F6: =IF(A6="","",COUNTIF('Holdings'!$A$4:$A$2503,A6)) | G6: =IF(A6="","",COUNTIF('Access'!$B$4:$B$1503,A6)) | H6: =IF(A6="","",IF(COUNTIF($A$4:$A$1003,A6)>1,"Duplicate holder ID",IF(OR(B6="",C6=""),"Missing required field",IF(F6=0,"No holdings",IF(AND(G6=0,A6<>"LKB-GROUP"),"No login (ok if not invited)","OK")))))
F7: =IF(A7="","",COUNTIF('Holdings'!$A$4:$A$2503,A7)) | G7: =IF(A7="","",COUNTIF('Access'!$B$4:$B$1503,A7)) | H7: =IF(A7="","",IF(COUNTIF($A$4:$A$1003,A7)>1,"Duplicate holder ID",IF(OR(B7="",C7=""),"Missing required field",IF(F7=0,"No holdings",IF(AND(G7=0,A7<>"LKB-GROUP"),"No login (ok if not invited)","OK")))))
F8: =IF(A8="","",COUNTIF('Holdings'!$A$4:$A$2503,A8)) | G8: =IF(A8="","",COUNTIF('Access'!$B$4:$B$1503,A8)) | H8: =IF(A8="","",IF(COUNTIF($A$4:$A$1003,A8)>1,"Duplicate holder ID",IF(OR(B8="",C8=""),"Missing required field",IF(F8=0,"No holdings",IF(AND(G8=0,A8<>"LKB-GROUP"),"No login (ok if not invited)","OK")))))
F9: =IF(A9="","",COUNTIF('Holdings'!$A$4:$A$2503,A9)) | G9: =IF(A9="","",COUNTIF('Access'!$B$4:$B$1503,A9)) | H9: =IF(A9="","",IF(COUNTIF($A$4:$A$1003,A9)>1,"Duplicate holder ID",IF(OR(B9="",C9=""),"Missing required field",IF(F9=0,"No holdings",IF(AND(G9=0,A9<>"LKB-GROUP"),"No login (ok if not invited)","OK")))))
F10: =IF(A10="","",COUNTIF('Holdings'!$A$4:$A$2503,A10)) | G10: =IF(A10="","",COUNTIF('Access'!$B$4:$B$1503,A10)) | H10: =IF(A10="","",IF(COUNTIF($A$4:$A$1003,A10)>1,"Duplicate holder ID",IF(OR(B10="",C10=""),"Missing required field",IF(F10=0,"No holdings",IF(AND(G10=0,A10<>"LKB-GROUP"),"No login (ok if not invited)","OK")))))
F11: =IF(A11="","",COUNTIF('Holdings'!$A$4:$A$2503,A11)) | G11: =IF(A11="","",COUNTIF('Access'!$B$4:$B$1503,A11)) | H11: =IF(A11="","",IF(COUNTIF($A$4:$A$1003,A11)>1,"Duplicate holder ID",IF(OR(B11="",C11=""),"Missing required field",IF(F11=0,"No holdings",IF(AND(G11=0,A11<>"LKB-GROUP"),"No login (ok if not invited)","OK")))))
F12: =IF(A12="","",COUNTIF('Holdings'!$A$4:$A$2503,A12)) | G12: =IF(A12="","",COUNTIF('Access'!$B$4:$B$1503,A12)) | H12: =IF(A12="","",IF(COUNTIF($A$4:$A$1003,A12)>1,"Duplicate holder ID",IF(OR(B12="",C12=""),"Missing required field",IF(F12=0,"No holdings",IF(AND(G12=0,A12<>"LKB-GROUP"),"No login (ok if not invited)","OK")))))
F13: =IF(A13="","",COUNTIF('Holdings'!$A$4:$A$2503,A13)) | G13: =IF(A13="","",COUNTIF('Access'!$B$4:$B$1503,A13)) | H13: =IF(A13="","",IF(COUNTIF($A$4:$A$1003,A13)>1,"Duplicate holder ID",IF(OR(B13="",C13=""),"Missing required field",IF(F13=0,"No holdings",IF(AND(G13=0,A13<>"LKB-GROUP"),"No login (ok if not invited)","OK")))))
F14: =IF(A14="","",COUNTIF('Holdings'!$A$4:$A$2503,A14)) | G14: =IF(A14="","",COUNTIF('Access'!$B$4:$B$1503,A14)) | H14: =IF(A14="","",IF(COUNTIF($A$4:$A$1003,A14)>1,"Duplicate holder ID",IF(OR(B14="",C14=""),"Missing required field",IF(F14=0,"No holdings",IF(AND(G14=0,A14<>"LKB-GROUP"),"No login (ok if not invited)","OK")))))
F15: =IF(A15="","",COUNTIF('Holdings'!$A$4:$A$2503,A15)) | G15: =IF(A15="","",COUNTIF('Access'!$B$4:$B$1503,A15)) | H15: =IF(A15="","",IF(COUNTIF($A$4:$A$1003,A15)>1,"Duplicate holder ID",IF(OR(B15="",C15=""),"Missing required field",IF(F15=0,"No holdings",IF(AND(G15=0,A15<>"LKB-GROUP"),"No login (ok if not invited)","OK")))))
F16: =IF(A16="","",COUNTIF('Holdings'!$A$4:$A$2503,A16)) | G16: =IF(A16="","",COUNTIF('Access'!$B$4:$B$1503,A16)) | H16: =IF(A16="","",IF(COUNTIF($A$4:$A$1003,A16)>1,"Duplicate holder ID",IF(OR(B16="",C16=""),"Missing required field",IF(F16=0,"No holdings",IF(AND(G16=0,A16<>"LKB-GROUP"),"No login (ok if not invited)","OK")))))
... F1003: =IF(A1003="","",COUNTIF('Holdings'!$A$4:$A$2503,A1003)) | G1003: =IF(A1003="","",COUNTIF('Access'!$B$4:$B$1503,A1003)) | H1003: =IF(A1003="","",IF(COUNTIF($A$4:$A$1003,A1003)>1,"Duplicate holder ID",IF(OR(B1003="",C1003=""),"Missing required field",IF(F1003=0,"No holdings",IF(AND(G1003=0,A1003<>"LKB-GROUP"),"No login (ok if not invited)","OK")))))

Sheet People
A1: People (portal logins) | C1: Everyone who signs in. One row per email address; one person can see many holders across many companies.
A2: Email * | B2: First name | C2: Last name | D2: Phone | E2: Roles | F2: Email notifications | G2: Notes | H2: Holders they see | I2: Companies they see | J2: Check
A3: jane@example.com | B3: Jane | C3: Citizen | D3: +61 400 000 000 | F3: Yes | K3: ← example row, not imported
H4: =IF(A4="","",COUNTIF('Access'!$A$4:$A$1503,A4)) | I4: {=IF(A4="","",_xlfn.TEXTJOIN(", ",TRUE,IF(('Companies'!$A$4:$A$63<>"")*(COUNTIFS('Access'!$A$4:$A$1503,A4,'Access'!$F$4:$F$1503,"*"&'Companies'!$A$4:$A$63&"*")>0),'Companies'!$A$4:$A$63,"")))} | J4: =IF(A4="","",IF(COUNTIF($A$4:$A$1003,A4)>1,"Duplicate email",IF(ISERROR(FIND("@",A4)),"Not an email address",IF(AND(H4=0,E4=""),"Investor without holders","OK"))))
H5: =IF(A5="","",COUNTIF('Access'!$A$4:$A$1503,A5)) | I5: {=IF(A5="","",_xlfn.TEXTJOIN(", ",TRUE,IF(('Companies'!$A$4:$A$63<>"")*(COUNTIFS('Access'!$A$4:$A$1503,A5,'Access'!$F$4:$F$1503,"*"&'Companies'!$A$4:$A$63&"*")>0),'Companies'!$A$4:$A$63,"")))} | J5: =IF(A5="","",IF(COUNTIF($A$4:$A$1003,A5)>1,"Duplicate email",IF(ISERROR(FIND("@",A5)),"Not an email address",IF(AND(H5=0,E5=""),"Investor without holders","OK"))))
H6: =IF(A6="","",COUNTIF('Access'!$A$4:$A$1503,A6)) | I6: {=IF(A6="","",_xlfn.TEXTJOIN(", ",TRUE,IF(('Companies'!$A$4:$A$63<>"")*(COUNTIFS('Access'!$A$4:$A$1503,A6,'Access'!$F$4:$F$1503,"*"&'Companies'!$A$4:$A$63&"*")>0),'Companies'!$A$4:$A$63,"")))} | J6: =IF(A6="","",IF(COUNTIF($A$4:$A$1003,A6)>1,"Duplicate email",IF(ISERROR(FIND("@",A6)),"Not an email address",IF(AND(H6=0,E6=""),"Investor without holders","OK"))))
H7: =IF(A7="","",COUNTIF('Access'!$A$4:$A$1503,A7)) | I7: {=IF(A7="","",_xlfn.TEXTJOIN(", ",TRUE,IF(('Companies'!$A$4:$A$63<>"")*(COUNTIFS('Access'!$A$4:$A$1503,A7,'Access'!$F$4:$F$1503,"*"&'Companies'!$A$4:$A$63&"*")>0),'Companies'!$A$4:$A$63,"")))} | J7: =IF(A7="","",IF(COUNTIF($A$4:$A$1003,A7)>1,"Duplicate email",IF(ISERROR(FIND("@",A7)),"Not an email address",IF(AND(H7=0,E7=""),"Investor without holders","OK"))))
H8: =IF(A8="","",COUNTIF('Access'!$A$4:$A$1503,A8)) | I8: {=IF(A8="","",_xlfn.TEXTJOIN(", ",TRUE,IF(('Companies'!$A$4:$A$63<>"")*(COUNTIFS('Access'!$A$4:$A$1503,A8,'Access'!$F$4:$F$1503,"*"&'Companies'!$A$4:$A$63&"*")>0),'Companies'!$A$4:$A$63,"")))} | J8: =IF(A8="","",IF(COUNTIF($A$4:$A$1003,A8)>1,"Duplicate email",IF(ISERROR(FIND("@",A8)),"Not an email address",IF(AND(H8=0,E8=""),"Investor without holders","OK"))))
H9: =IF(A9="","",COUNTIF('Access'!$A$4:$A$1503,A9)) | I9: {=IF(A9="","",_xlfn.TEXTJOIN(", ",TRUE,IF(('Companies'!$A$4:$A$63<>"")*(COUNTIFS('Access'!$A$4:$A$1503,A9,'Access'!$F$4:$F$1503,"*"&'Companies'!$A$4:$A$63&"*")>0),'Companies'!$A$4:$A$63,"")))} | J9: =IF(A9="","",IF(COUNTIF($A$4:$A$1003,A9)>1,"Duplicate email",IF(ISERROR(FIND("@",A9)),"Not an email address",IF(AND(H9=0,E9=""),"Investor without holders","OK"))))
H10: =IF(A10="","",COUNTIF('Access'!$A$4:$A$1503,A10)) | I10: {=IF(A10="","",_xlfn.TEXTJOIN(", ",TRUE,IF(('Companies'!$A$4:$A$63<>"")*(COUNTIFS('Access'!$A$4:$A$1503,A10,'Access'!$F$4:$F$1503,"*"&'Companies'!$A$4:$A$63&"*")>0),'Companies'!$A$4:$A$63,"")))} | J10: =IF(A10="","",IF(COUNTIF($A$4:$A$1003,A10)>1,"Duplicate email",IF(ISERROR(FIND("@",A10)),"Not an email address",IF(AND(H10=0,E10=""),"Investor without holders","OK"))))
H11: =IF(A11="","",COUNTIF('Access'!$A$4:$A$1503,A11)) | I11: {=IF(A11="","",_xlfn.TEXTJOIN(", ",TRUE,IF(('Companies'!$A$4:$A$63<>"")*(COUNTIFS('Access'!$A$4:$A$1503,A11,'Access'!$F$4:$F$1503,"*"&'Companies'!$A$4:$A$63&"*")>0),'Companies'!$A$4:$A$63,"")))} | J11: =IF(A11="","",IF(COUNTIF($A$4:$A$1003,A11)>1,"Duplicate email",IF(ISERROR(FIND("@",A11)),"Not an email address",IF(AND(H11=0,E11=""),"Investor without holders","OK"))))
H12: =IF(A12="","",COUNTIF('Access'!$A$4:$A$1503,A12)) | I12: {=IF(A12="","",_xlfn.TEXTJOIN(", ",TRUE,IF(('Companies'!$A$4:$A$63<>"")*(COUNTIFS('Access'!$A$4:$A$1503,A12,'Access'!$F$4:$F$1503,"*"&'Companies'!$A$4:$A$63&"*")>0),'Companies'!$A$4:$A$63,"")))} | J12: =IF(A12="","",IF(COUNTIF($A$4:$A$1003,A12)>1,"Duplicate email",IF(ISERROR(FIND("@",A12)),"Not an email address",IF(AND(H12=0,E12=""),"Investor without holders","OK"))))
H13: =IF(A13="","",COUNTIF('Access'!$A$4:$A$1503,A13)) | I13: {=IF(A13="","",_xlfn.TEXTJOIN(", ",TRUE,IF(('Companies'!$A$4:$A$63<>"")*(COUNTIFS('Access'!$A$4:$A$1503,A13,'Access'!$F$4:$F$1503,"*"&'Companies'!$A$4:$A$63&"*")>0),'Companies'!$A$4:$A$63,"")))} | J13: =IF(A13="","",IF(COUNTIF($A$4:$A$1003,A13)>1,"Duplicate email",IF(ISERROR(FIND("@",A13)),"Not an email address",IF(AND(H13=0,E13=""),"Investor without holders","OK"))))
H14: =IF(A14="","",COUNTIF('Access'!$A$4:$A$1503,A14)) | I14: {=IF(A14="","",_xlfn.TEXTJOIN(", ",TRUE,IF(('Companies'!$A$4:$A$63<>"")*(COUNTIFS('Access'!$A$4:$A$1503,A14,'Access'!$F$4:$F$1503,"*"&'Companies'!$A$4:$A$63&"*")>0),'Companies'!$A$4:$A$63,"")))} | J14: =IF(A14="","",IF(COUNTIF($A$4:$A$1003,A14)>1,"Duplicate email",IF(ISERROR(FIND("@",A14)),"Not an email address",IF(AND(H14=0,E14=""),"Investor without holders","OK"))))
H15: =IF(A15="","",COUNTIF('Access'!$A$4:$A$1503,A15)) | I15: {=IF(A15="","",_xlfn.TEXTJOIN(", ",TRUE,IF(('Companies'!$A$4:$A$63<>"")*(COUNTIFS('Access'!$A$4:$A$1503,A15,'Access'!$F$4:$F$1503,"*"&'Companies'!$A$4:$A$63&"*")>0),'Companies'!$A$4:$A$63,"")))} | J15: =IF(A15="","",IF(COUNTIF($A$4:$A$1003,A15)>1,"Duplicate email",IF(ISERROR(FIND("@",A15)),"Not an email address",IF(AND(H15=0,E15=""),"Investor without holders","OK"))))
... H1003: =IF(A1003="","",COUNTIF('Access'!$A$4:$A$1503,A1003)) | I1003: {=IF(A1003="","",_xlfn.TEXTJOIN(", ",TRUE,IF(('Companies'!$A$4:$A$63<>"")*(COUNTIFS('Access'!$A$4:$A$1503,A1003,'Access'!$F$4:$F$1503,"*"&'Companies'!$A$4:$A$63&"*")>0),'Companies'!$A$4:$A$63,"")))} | J1003: =IF(A1003="","",IF(COUNTIF($A$4:$A$1003,A1003)>1,"Duplicate email",IF(ISERROR(FIND("@",A1003)),"Not an email address",IF(AND(H1003=0,E1003=""),"Investor without holders","OK"))))

Sheet Access
A1: Access (who sees which holder) | C1: Links a login to the holders it may see. A person who holds via a trust and personally has two rows.
A2: Email * | B2: Holder ID * | C2: Access * | D2: Notes | E2: Holder name | F2: Companies (via holdings) | G2: Check
A3: jane@example.com | B3: H-0001 | C3: Owner | H3: ← example row, not imported
E4: =IF(B4="","",IFERROR(INDEX('Holders'!$B$4:$B$1003,MATCH(B4,'Holders'!$A$4:$A$1003,0)),"")) | F4: {=IF(B4="","",_xlfn.TEXTJOIN(", ",TRUE,IF(('Companies'!$A$4:$A$63<>"")*(COUNTIFS('Holdings'!$A$4:$A$2503,B4,'Holdings'!$J$4:$J$2503,'Companies'!$A$4:$A$63,'Holdings'!$L$4:$L$2503,"Yes",'Holdings'!$C$4:$C$2503,">0")>0),'Companies'!$A$4:$A$63,"")))} | G4: =IF(A4="","",IF(COUNTIF('People'!$A$4:$A$1003,A4)=0,"Email not on People",IF(COUNTIF('Holders'!$A$4:$A$1003,B4)=0,"Unknown holder ID",IF(COUNTIFS($A$4:$A$1503,A4,$B$4:$B$1503,B4)>1,"Duplicate link",IF(C4="","Missing access","OK")))))
E5: =IF(B5="","",IFERROR(INDEX('Holders'!$B$4:$B$1003,MATCH(B5,'Holders'!$A$4:$A$1003,0)),"")) | F5: {=IF(B5="","",_xlfn.TEXTJOIN(", ",TRUE,IF(('Companies'!$A$4:$A$63<>"")*(COUNTIFS('Holdings'!$A$4:$A$2503,B5,'Holdings'!$J$4:$J$2503,'Companies'!$A$4:$A$63,'Holdings'!$L$4:$L$2503,"Yes",'Holdings'!$C$4:$C$2503,">0")>0),'Companies'!$A$4:$A$63,"")))} | G5: =IF(A5="","",IF(COUNTIF('People'!$A$4:$A$1003,A5)=0,"Email not on People",IF(COUNTIF('Holders'!$A$4:$A$1003,B5)=0,"Unknown holder ID",IF(COUNTIFS($A$4:$A$1503,A5,$B$4:$B$1503,B5)>1,"Duplicate link",IF(C5="","Missing access","OK")))))
E6: =IF(B6="","",IFERROR(INDEX('Holders'!$B$4:$B$1003,MATCH(B6,'Holders'!$A$4:$A$1003,0)),"")) | F6: {=IF(B6="","",_xlfn.TEXTJOIN(", ",TRUE,IF(('Companies'!$A$4:$A$63<>"")*(COUNTIFS('Holdings'!$A$4:$A$2503,B6,'Holdings'!$J$4:$J$2503,'Companies'!$A$4:$A$63,'Holdings'!$L$4:$L$2503,"Yes",'Holdings'!$C$4:$C$2503,">0")>0),'Companies'!$A$4:$A$63,"")))} | G6: =IF(A6="","",IF(COUNTIF('People'!$A$4:$A$1003,A6)=0,"Email not on People",IF(COUNTIF('Holders'!$A$4:$A$1003,B6)=0,"Unknown holder ID",IF(COUNTIFS($A$4:$A$1503,A6,$B$4:$B$1503,B6)>1,"Duplicate link",IF(C6="","Missing access","OK")))))
E7: =IF(B7="","",IFERROR(INDEX('Holders'!$B$4:$B$1003,MATCH(B7,'Holders'!$A$4:$A$1003,0)),"")) | F7: {=IF(B7="","",_xlfn.TEXTJOIN(", ",TRUE,IF(('Companies'!$A$4:$A$63<>"")*(COUNTIFS('Holdings'!$A$4:$A$2503,B7,'Holdings'!$J$4:$J$2503,'Companies'!$A$4:$A$63,'Holdings'!$L$4:$L$2503,"Yes",'Holdings'!$C$4:$C$2503,">0")>0),'Companies'!$A$4:$A$63,"")))} | G7: =IF(A7="","",IF(COUNTIF('People'!$A$4:$A$1003,A7)=0,"Email not on People",IF(COUNTIF('Holders'!$A$4:$A$1003,B7)=0,"Unknown holder ID",IF(COUNTIFS($A$4:$A$1503,A7,$B$4:$B$1503,B7)>1,"Duplicate link",IF(C7="","Missing access","OK")))))
E8: =IF(B8="","",IFERROR(INDEX('Holders'!$B$4:$B$1003,MATCH(B8,'Holders'!$A$4:$A$1003,0)),"")) | F8: {=IF(B8="","",_xlfn.TEXTJOIN(", ",TRUE,IF(('Companies'!$A$4:$A$63<>"")*(COUNTIFS('Holdings'!$A$4:$A$2503,B8,'Holdings'!$J$4:$J$2503,'Companies'!$A$4:$A$63,'Holdings'!$L$4:$L$2503,"Yes",'Holdings'!$C$4:$C$2503,">0")>0),'Companies'!$A$4:$A$63,"")))} | G8: =IF(A8="","",IF(COUNTIF('People'!$A$4:$A$1003,A8)=0,"Email not on People",IF(COUNTIF('Holders'!$A$4:$A$1003,B8)=0,"Unknown holder ID",IF(COUNTIFS($A$4:$A$1503,A8,$B$4:$B$1503,B8)>1,"Duplicate link",IF(C8="","Missing access","OK")))))
E9: =IF(B9="","",IFERROR(INDEX('Holders'!$B$4:$B$1003,MATCH(B9,'Holders'!$A$4:$A$1003,0)),"")) | F9: {=IF(B9="","",_xlfn.TEXTJOIN(", ",TRUE,IF(('Companies'!$A$4:$A$63<>"")*(COUNTIFS('Holdings'!$A$4:$A$2503,B9,'Holdings'!$J$4:$J$2503,'Companies'!$A$4:$A$63,'Holdings'!$L$4:$L$2503,"Yes",'Holdings'!$C$4:$C$2503,">0")>0),'Companies'!$A$4:$A$63,"")))} | G9: =IF(A9="","",IF(COUNTIF('People'!$A$4:$A$1003,A9)=0,"Email not on People",IF(COUNTIF('Holders'!$A$4:$A$1003,B9)=0,"Unknown holder ID",IF(COUNTIFS($A$4:$A$1503,A9,$B$4:$B$1503,B9)>1,"Duplicate link",IF(C9="","Missing access","OK")))))
E10: =IF(B10="","",IFERROR(INDEX('Holders'!$B$4:$B$1003,MATCH(B10,'Holders'!$A$4:$A$1003,0)),"")) | F10: {=IF(B10="","",_xlfn.TEXTJOIN(", ",TRUE,IF(('Companies'!$A$4:$A$63<>"")*(COUNTIFS('Holdings'!$A$4:$A$2503,B10,'Holdings'!$J$4:$J$2503,'Companies'!$A$4:$A$63,'Holdings'!$L$4:$L$2503,"Yes",'Holdings'!$C$4:$C$2503,">0")>0),'Companies'!$A$4:$A$63,"")))} | G10: =IF(A10="","",IF(COUNTIF('People'!$A$4:$A$1003,A10)=0,"Email not on People",IF(COUNTIF('Holders'!$A$4:$A$1003,B10)=0,"Unknown holder ID",IF(COUNTIFS($A$4:$A$1503,A10,$B$4:$B$1503,B10)>1,"Duplicate link",IF(C10="","Missing access","OK")))))
E11: =IF(B11="","",IFERROR(INDEX('Holders'!$B$4:$B$1003,MATCH(B11,'Holders'!$A$4:$A$1003,0)),"")) | F11: {=IF(B11="","",_xlfn.TEXTJOIN(", ",TRUE,IF(('Companies'!$A$4:$A$63<>"")*(COUNTIFS('Holdings'!$A$4:$A$2503,B11,'Holdings'!$J$4:$J$2503,'Companies'!$A$4:$A$63,'Holdings'!$L$4:$L$2503,"Yes",'Holdings'!$C$4:$C$2503,">0")>0),'Companies'!$A$4:$A$63,"")))} | G11: =IF(A11="","",IF(COUNTIF('People'!$A$4:$A$1003,A11)=0,"Email not on People",IF(COUNTIF('Holders'!$A$4:$A$1003,B11)=0,"Unknown holder ID",IF(COUNTIFS($A$4:$A$1503,A11,$B$4:$B$1503,B11)>1,"Duplicate link",IF(C11="","Missing access","OK")))))
E12: =IF(B12="","",IFERROR(INDEX('Holders'!$B$4:$B$1003,MATCH(B12,'Holders'!$A$4:$A$1003,0)),"")) | F12: {=IF(B12="","",_xlfn.TEXTJOIN(", ",TRUE,IF(('Companies'!$A$4:$A$63<>"")*(COUNTIFS('Holdings'!$A$4:$A$2503,B12,'Holdings'!$J$4:$J$2503,'Companies'!$A$4:$A$63,'Holdings'!$L$4:$L$2503,"Yes",'Holdings'!$C$4:$C$2503,">0")>0),'Companies'!$A$4:$A$63,"")))} | G12: =IF(A12="","",IF(COUNTIF('People'!$A$4:$A$1003,A12)=0,"Email not on People",IF(COUNTIF('Holders'!$A$4:$A$1003,B12)=0,"Unknown holder ID",IF(COUNTIFS($A$4:$A$1503,A12,$B$4:$B$1503,B12)>1,"Duplicate link",IF(C12="","Missing access","OK")))))
E13: =IF(B13="","",IFERROR(INDEX('Holders'!$B$4:$B$1003,MATCH(B13,'Holders'!$A$4:$A$1003,0)),"")) | F13: {=IF(B13="","",_xlfn.TEXTJOIN(", ",TRUE,IF(('Companies'!$A$4:$A$63<>"")*(COUNTIFS('Holdings'!$A$4:$A$2503,B13,'Holdings'!$J$4:$J$2503,'Companies'!$A$4:$A$63,'Holdings'!$L$4:$L$2503,"Yes",'Holdings'!$C$4:$C$2503,">0")>0),'Companies'!$A$4:$A$63,"")))} | G13: =IF(A13="","",IF(COUNTIF('People'!$A$4:$A$1003,A13)=0,"Email not on People",IF(COUNTIF('Holders'!$A$4:$A$1003,B13)=0,"Unknown holder ID",IF(COUNTIFS($A$4:$A$1503,A13,$B$4:$B$1503,B13)>1,"Duplicate link",IF(C13="","Missing access","OK")))))
E14: =IF(B14="","",IFERROR(INDEX('Holders'!$B$4:$B$1003,MATCH(B14,'Holders'!$A$4:$A$1003,0)),"")) | F14: {=IF(B14="","",_xlfn.TEXTJOIN(", ",TRUE,IF(('Companies'!$A$4:$A$63<>"")*(COUNTIFS('Holdings'!$A$4:$A$2503,B14,'Holdings'!$J$4:$J$2503,'Companies'!$A$4:$A$63,'Holdings'!$L$4:$L$2503,"Yes",'Holdings'!$C$4:$C$2503,">0")>0),'Companies'!$A$4:$A$63,"")))} | G14: =IF(A14="","",IF(COUNTIF('People'!$A$4:$A$1003,A14)=0,"Email not on People",IF(COUNTIF('Holders'!$A$4:$A$1003,B14)=0,"Unknown holder ID",IF(COUNTIFS($A$4:$A$1503,A14,$B$4:$B$1503,B14)>1,"Duplicate link",IF(C14="","Missing access","OK")))))
E15: =IF(B15="","",IFERROR(INDEX('Holders'!$B$4:$B$1003,MATCH(B15,'Holders'!$A$4:$A$1003,0)),"")) | F15: {=IF(B15="","",_xlfn.TEXTJOIN(", ",TRUE,IF(('Companies'!$A$4:$A$63<>"")*(COUNTIFS('Holdings'!$A$4:$A$2503,B15,'Holdings'!$J$4:$J$2503,'Companies'!$A$4:$A$63,'Holdings'!$L$4:$L$2503,"Yes",'Holdings'!$C$4:$C$2503,">0")>0),'Companies'!$A$4:$A$63,"")))} | G15: =IF(A15="","",IF(COUNTIF('People'!$A$4:$A$1003,A15)=0,"Email not on People",IF(COUNTIF('Holders'!$A$4:$A$1003,B15)=0,"Unknown holder ID",IF(COUNTIFS($A$4:$A$1503,A15,$B$4:$B$1503,B15)>1,"Duplicate link",IF(C15="","Missing access","OK")))))
... E1503: =IF(B1503="","",IFERROR(INDEX('Holders'!$B$4:$B$1003,MATCH(B1503,'Holders'!$A$4:$A$1003,0)),"")) | F1503: {=IF(B1503="","",_xlfn.TEXTJOIN(", ",TRUE,IF(('Companies'!$A$4:$A$63<>"")*(COUNTIFS('Holdings'!$A$4:$A$2503,B1503,'Holdings'!$J$4:$J$2503,'Companies'!$A$4:$A$63,'Holdings'!$L$4:$L$2503,"Yes",'Holdings'!$C$4:$C$2503,">0")>0),'Companies'!$A$4:$A$63,"")))} | G1503: =IF(A1503="","",IF(COUNTIF('People'!$A$4:$A$1003,A1503)=0,"Email not on People",IF(COUNTIF('Holders'!$A$4:$A$1003,B1503)=0,"Unknown holder ID",IF(COUNTIFS($A$4:$A$1503,A1503,$B$4:$B$1503,B1503)>1,"Duplicate link",IF(C1503="","Missing access","OK")))))

Sheet Holdings
A1: Holdings | C1: Shares held, per holder, class and date. Add a new row when a holding changes; keep old rows as history. The latest date counts.
A2: Holder ID * | B2: Class code * | C2: Shares * | D2: As at * | E2: Register ref | F2: Source | G2: Notes | H2: Exercise price | I2: Expires on | J2: Company | K2: Holder name | L2: Latest? | M2: Counts toward % | N2: Check
A3: H-0001 | B3: EZF-ORD | C3: 25000 | D3: 46203 | F3: Share register | O3: ← example row, not imported
J4: =IF(B4="","",IFERROR(INDEX('Share classes'!$A$4:$A$203,MATCH(B4,'Share classes'!$B$4:$B$203,0)),"")) | K4: =IF(A4="","",IFERROR(INDEX('Holders'!$B$4:$B$1003,MATCH(A4,'Holders'!$A$4:$A$1003,0)),"")) | L4: =IF(OR(A4="",B4="",D4=""),"",IF(D4=_xlfn.MAXIFS($D$4:$D$2503,$A$4:$A$2503,A4,$B$4:$B$2503,B4),"Yes","No")) | M4: =IF(B4="","",IFERROR(INDEX('Share classes'!$F$4:$F$203,MATCH(B4,'Share classes'!$B$4:$B$203,0)),"")) | N4: =IF(A4="","",IF(K4="","Unknown holder ID",IF(J4="","Unknown class code",IF(OR(C4="",D4=""),"Missing shares or date",IF(OR(C4<0,C4<>INT(C4)),"Shares must be a whole number",IF(COUNTIFS($A$4:$A$2503,A4,$B$4:$B$2503,B4,$D$4:$D$2503,D4)>1,"Duplicate row (same date)","OK"))))))
J5: =IF(B5="","",IFERROR(INDEX('Share classes'!$A$4:$A$203,MATCH(B5,'Share classes'!$B$4:$B$203,0)),"")) | K5: =IF(A5="","",IFERROR(INDEX('Holders'!$B$4:$B$1003,MATCH(A5,'Holders'!$A$4:$A$1003,0)),"")) | L5: =IF(OR(A5="",B5="",D5=""),"",IF(D5=_xlfn.MAXIFS($D$4:$D$2503,$A$4:$A$2503,A5,$B$4:$B$2503,B5),"Yes","No")) | M5: =IF(B5="","",IFERROR(INDEX('Share classes'!$F$4:$F$203,MATCH(B5,'Share classes'!$B$4:$B$203,0)),"")) | N5: =IF(A5="","",IF(K5="","Unknown holder ID",IF(J5="","Unknown class code",IF(OR(C5="",D5=""),"Missing shares or date",IF(OR(C5<0,C5<>INT(C5)),"Shares must be a whole number",IF(COUNTIFS($A$4:$A$2503,A5,$B$4:$B$2503,B5,$D$4:$D$2503,D5)>1,"Duplicate row (same date)","OK"))))))
J6: =IF(B6="","",IFERROR(INDEX('Share classes'!$A$4:$A$203,MATCH(B6,'Share classes'!$B$4:$B$203,0)),"")) | K6: =IF(A6="","",IFERROR(INDEX('Holders'!$B$4:$B$1003,MATCH(A6,'Holders'!$A$4:$A$1003,0)),"")) | L6: =IF(OR(A6="",B6="",D6=""),"",IF(D6=_xlfn.MAXIFS($D$4:$D$2503,$A$4:$A$2503,A6,$B$4:$B$2503,B6),"Yes","No")) | M6: =IF(B6="","",IFERROR(INDEX('Share classes'!$F$4:$F$203,MATCH(B6,'Share classes'!$B$4:$B$203,0)),"")) | N6: =IF(A6="","",IF(K6="","Unknown holder ID",IF(J6="","Unknown class code",IF(OR(C6="",D6=""),"Missing shares or date",IF(OR(C6<0,C6<>INT(C6)),"Shares must be a whole number",IF(COUNTIFS($A$4:$A$2503,A6,$B$4:$B$2503,B6,$D$4:$D$2503,D6)>1,"Duplicate row (same date)","OK"))))))
J7: =IF(B7="","",IFERROR(INDEX('Share classes'!$A$4:$A$203,MATCH(B7,'Share classes'!$B$4:$B$203,0)),"")) | K7: =IF(A7="","",IFERROR(INDEX('Holders'!$B$4:$B$1003,MATCH(A7,'Holders'!$A$4:$A$1003,0)),"")) | L7: =IF(OR(A7="",B7="",D7=""),"",IF(D7=_xlfn.MAXIFS($D$4:$D$2503,$A$4:$A$2503,A7,$B$4:$B$2503,B7),"Yes","No")) | M7: =IF(B7="","",IFERROR(INDEX('Share classes'!$F$4:$F$203,MATCH(B7,'Share classes'!$B$4:$B$203,0)),"")) | N7: =IF(A7="","",IF(K7="","Unknown holder ID",IF(J7="","Unknown class code",IF(OR(C7="",D7=""),"Missing shares or date",IF(OR(C7<0,C7<>INT(C7)),"Shares must be a whole number",IF(COUNTIFS($A$4:$A$2503,A7,$B$4:$B$2503,B7,$D$4:$D$2503,D7)>1,"Duplicate row (same date)","OK"))))))
J8: =IF(B8="","",IFERROR(INDEX('Share classes'!$A$4:$A$203,MATCH(B8,'Share classes'!$B$4:$B$203,0)),"")) | K8: =IF(A8="","",IFERROR(INDEX('Holders'!$B$4:$B$1003,MATCH(A8,'Holders'!$A$4:$A$1003,0)),"")) | L8: =IF(OR(A8="",B8="",D8=""),"",IF(D8=_xlfn.MAXIFS($D$4:$D$2503,$A$4:$A$2503,A8,$B$4:$B$2503,B8),"Yes","No")) | M8: =IF(B8="","",IFERROR(INDEX('Share classes'!$F$4:$F$203,MATCH(B8,'Share classes'!$B$4:$B$203,0)),"")) | N8: =IF(A8="","",IF(K8="","Unknown holder ID",IF(J8="","Unknown class code",IF(OR(C8="",D8=""),"Missing shares or date",IF(OR(C8<0,C8<>INT(C8)),"Shares must be a whole number",IF(COUNTIFS($A$4:$A$2503,A8,$B$4:$B$2503,B8,$D$4:$D$2503,D8)>1,"Duplicate row (same date)","OK"))))))
J9: =IF(B9="","",IFERROR(INDEX('Share classes'!$A$4:$A$203,MATCH(B9,'Share classes'!$B$4:$B$203,0)),"")) | K9: =IF(A9="","",IFERROR(INDEX('Holders'!$B$4:$B$1003,MATCH(A9,'Holders'!$A$4:$A$1003,0)),"")) | L9: =IF(OR(A9="",B9="",D9=""),"",IF(D9=_xlfn.MAXIFS($D$4:$D$2503,$A$4:$A$2503,A9,$B$4:$B$2503,B9),"Yes","No")) | M9: =IF(B9="","",IFERROR(INDEX('Share classes'!$F$4:$F$203,MATCH(B9,'Share classes'!$B$4:$B$203,0)),"")) | N9: =IF(A9="","",IF(K9="","Unknown holder ID",IF(J9="","Unknown class code",IF(OR(C9="",D9=""),"Missing shares or date",IF(OR(C9<0,C9<>INT(C9)),"Shares must be a whole number",IF(COUNTIFS($A$4:$A$2503,A9,$B$4:$B$2503,B9,$D$4:$D$2503,D9)>1,"Duplicate row (same date)","OK"))))))
J10: =IF(B10="","",IFERROR(INDEX('Share classes'!$A$4:$A$203,MATCH(B10,'Share classes'!$B$4:$B$203,0)),"")) | K10: =IF(A10="","",IFERROR(INDEX('Holders'!$B$4:$B$1003,MATCH(A10,'Holders'!$A$4:$A$1003,0)),"")) | L10: =IF(OR(A10="",B10="",D10=""),"",IF(D10=_xlfn.MAXIFS($D$4:$D$2503,$A$4:$A$2503,A10,$B$4:$B$2503,B10),"Yes","No")) | M10: =IF(B10="","",IFERROR(INDEX('Share classes'!$F$4:$F$203,MATCH(B10,'Share classes'!$B$4:$B$203,0)),"")) | N10: =IF(A10="","",IF(K10="","Unknown holder ID",IF(J10="","Unknown class code",IF(OR(C10="",D10=""),"Missing shares or date",IF(OR(C10<0,C10<>INT(C10)),"Shares must be a whole number",IF(COUNTIFS($A$4:$A$2503,A10,$B$4:$B$2503,B10,$D$4:$D$2503,D10)>1,"Duplicate row (same date)","OK"))))))
J11: =IF(B11="","",IFERROR(INDEX('Share classes'!$A$4:$A$203,MATCH(B11,'Share classes'!$B$4:$B$203,0)),"")) | K11: =IF(A11="","",IFERROR(INDEX('Holders'!$B$4:$B$1003,MATCH(A11,'Holders'!$A$4:$A$1003,0)),"")) | L11: =IF(OR(A11="",B11="",D11=""),"",IF(D11=_xlfn.MAXIFS($D$4:$D$2503,$A$4:$A$2503,A11,$B$4:$B$2503,B11),"Yes","No")) | M11: =IF(B11="","",IFERROR(INDEX('Share classes'!$F$4:$F$203,MATCH(B11,'Share classes'!$B$4:$B$203,0)),"")) | N11: =IF(A11="","",IF(K11="","Unknown holder ID",IF(J11="","Unknown class code",IF(OR(C11="",D11=""),"Missing shares or date",IF(OR(C11<0,C11<>INT(C11)),"Shares must be a whole number",IF(COUNTIFS($A$4:$A$2503,A11,$B$4:$B$2503,B11,$D$4:$D$2503,D11)>1,"Duplicate row (same date)","OK"))))))
